2020-09-03T11:30:33|CRITICAL|root|Unhandled exception:Traceback (most recent call last):
  File "C:\Users\OPT\anaconda3\envs\ScopeFoundry\lib\site-packages\ScopeFoundry\hardware.py", line 208, in enable_connection
    raise err
  File "C:\Users\OPT\anaconda3\envs\ScopeFoundry\lib\site-packages\ScopeFoundry\hardware.py", line 204, in enable_connection
    self.connect()
  File "D:\LabPrograms\ScopeFoundry_POLIMI\DMD_ScopeFoundry\DMDHardware.py", line 55, in connect
    self.dmd = DmdDeviceHID()
  File "D:\LabPrograms\ScopeFoundry_POLIMI\DMD_ScopeFoundry\DMDDeviceHID.py", line 33, in __init__
    self.device = hid.Device()
  File "C:\Users\OPT\anaconda3\envs\ScopeFoundry\lib\site-packages\hid\__init__.py", line 127, in __init__
    raise ValueError('specify vid/pid or path')
ValueError: specify vid/pid or path

